<?xml version="1.0" ?>
<!-- =================================================================================== -->
<!-- |    This document was autogenerated by xacro from rbvogui_xl_std.urdf.xacro      | -->
<!-- |    EDITING THIS FILE BY HAND IS NOT RECOMMENDED                                 | -->
<!-- =================================================================================== -->
<!-- RBVogui XL -->
<robot name="rbvogui">
  <!-- ***************** -->
  <!-- Imported elements -->
  <!-- ***************** -->
  <!-- First we import all posible elements defined in the urdf.xacro files. All these elements are defined as macro:xacros -->
  <!-- Source: https://en.wikipedia.org/wiki/List_of_moments_of_inertia-->
  <!-- in kg-->
  <!-- Source: https://en.wikipedia.org/wiki/List_of_moments_of_inertia-->
  <!-- Source: https://en.wikipedia.org/wiki/List_of_moments_of_inertia-->
  <!-- Source: https://en.wikipedia.org/wiki/List_of_moments_of_inertia-->
  <!-- source en.wikipedia.org/wiki/List_of_moments_of_inertia-->
  <!-- This file unifies all sensors that can be used on simulation, defined as xacro:macros -->
  <!-- Includes -->
  <!-- Includes -->
  <gazebo>
    <plugin filename="libgazebo_ros_control.so" name="ros_control">
      <!--<robotNamespace>/summit_xl</robotNamespace>-->
      <robotParam>robot_description</robotParam>
      <controlPeriod>0.001</controlPeriod>
      <robotSimType>gazebo_ros_control/DefaultRobotHWSim</robotSimType>
      <legacyModeNS>true</legacyModeNS>
    </plugin>
  </gazebo>
  <!-- *************** -->
  <!-- Robots Elements -->
  <!-- *************** -->
  <!-- Here we create the robot elements using the xacro:macros imported at the beggining of this file -->
  <link name="robot_base_footprint">
    <visual>
      <origin rpy="0 0 0" xyz="0 0 0"/>
      <geometry>
        <box size="0.001 0.001 0.001"/>
      </geometry>
    </visual>
  </link>
  <joint name="robot_base_footprint_joint" type="fixed">
    <origin rpy="0 0 0" xyz="0 0 0.1425"/>
    <!-- ${wheel_radius} property must be defined inside wheel description -->
    <parent link="robot_base_footprint"/>
    <child link="robot_base_link"/>
  </joint>
  <!-- BASE_LINK -->
  <link name="robot_base_link"/>
  <!-- Chassis -->
  <joint name="robot_chassis_joint" type="fixed">
    <origin rpy="0 0 0" xyz="0 0 0.23376"/>
    <parent link="robot_base_link"/>
    <child link="robot_chassis_link"/>
  </joint>
  <!-- Chassis -->
  <link name="robot_chassis_link">
    <inertial>
      <mass value="25.0"/>
      <origin xyz="0 0 0.376"/>
      <inertia ixx="1.8241020833333332" ixy="0" ixz="0" iyy="3.784270833333333" iyz="0" izz="4.707435416666667"/>
    </inertial>
    <visual>
      <origin rpy="0 0 0" xyz="0 0 0"/>
      <geometry>
        <mesh filename="package://rbvogui_description/meshes/bases/rbvogui_xl_chassis.stl"/>
      </geometry>
      <material name="darkgrey">
        <color rgba="0.1 0.1 0.1 1"/>
      </material>
    </visual>
    <collision>
      <origin rpy="0 0 0 " xyz="0 0 0"/>
      <geometry>
        <mesh filename="package://rbvogui_description/meshes/bases/rbvogui_xl_chassis.stl"/>
      </geometry>
    </collision>
  </link>
  <!-- Battery -->
  <joint name="robot_battery_joint" type="fixed">
    <origin rpy="0 0 0 " xyz="0 0 0"/>
    <parent link="robot_chassis_link"/>
    <child link="robot_battery_link"/>
  </joint>
  <!-- Battery -->
  <link name="robot_battery_link">
    <inertial>
      <mass value="20.0"/>
      <origin xyz="0 0 0"/>
      <inertia ixx="1.0" ixy="0.0" ixz="0.0" iyy="1.0" iyz="0.0" izz="1.0"/>
    </inertial>
    <visual>
      <origin rpy="0 0 0" xyz="0 0 0"/>
      <geometry>
        <mesh filename="package://rbvogui_description/meshes/bases/rbvogui_xl_battery.stl"/>
      </geometry>
      <material name="darkgrey">
        <color rgba="0.1 0.1 0.1 1"/>
      </material>
    </visual>
    <collision>
      <origin rpy="0 0 0 " xyz="0 0 0"/>
      <geometry>
        <mesh filename="package://rbvogui_description/meshes/bases/rbvogui_xl_battery.stl"/>
      </geometry>
    </collision>
  </link>
  <!-- Contactors -->
  <joint name="robot_contactors_joint" type="fixed">
    <origin rpy="0 0 0 " xyz="0.6405 0 0.10264"/>
    <parent link="robot_chassis_link"/>
    <child link="robot_contactors_link"/>
  </joint>
  <!-- Contactors -->
  <link name="robot_contactors_link">
    <visual>
      <origin rpy="0 0 0" xyz="0 0 0"/>
      <geometry>
        <mesh filename="package://rbvogui_description/meshes/bases/rbvogui_contactors.stl"/>
      </geometry>
      <material name="lighbrown">
        <color rgba="0.7 0.3 0.0 1"/>
      </material>
    </visual>
  </link>
  <!-- Logos -->
  <joint name="robot_base_logos_joint" type="fixed">
    <origin rpy="0 0 0 " xyz="0 0 -0.08376"/>
    <parent link="robot_chassis_link"/>
    <child link="robot_base_logos_link"/>
  </joint>
  <!-- Logos -->
  <link name="robot_base_logos_link">
    <visual>
      <origin rpy="0 0 0" xyz="0 0 -0.06"/>
      <geometry>
        <mesh filename="package://rbvogui_description/meshes/bases/rbvogui_logos.stl" scale="1.24 1.24 1"/>
      </geometry>
      <material name="lightred">
        <color rgba="0.9 0.2 0.2 1"/>
      </material>
    </visual>
  </link>
  <joint name="robot_leds_joint" type="fixed">
    <origin rpy="0 0 0 " xyz="0 0 0.12624"/>
    <parent link="robot_chassis_link"/>
    <child link="robot_leds_link"/>
  </joint>
  <link name="robot_leds_link">
    <visual>
      <origin rpy="0 0 0.0" xyz="0 0 0"/>
      <geometry>
        <mesh filename="package://rbvogui_description/meshes/bases/rbvogui_xl_leds.stl"/>
      </geometry>
      <material name="lightgreen">
        <color rgba="0.1 1.0 0.1 1"/>
      </material>
    </visual>
  </link>
  <gazebo reference="robot_base_link">
    <visual>
      <material>
        <ambient>0.0 0.0 0.0 1.0</ambient>
        <diffuse>0.2 0.2 0.2 1.0</diffuse>
        <specular>0.508273 0.508273 0.508273 1.0</specular>
        <emissive>0.0 0.0 0.0 0.0</emissive>
      </material>
    </visual>
  </gazebo>
  <gazebo reference="robot_chassis_link">
    <visual>
      <material>
        <ambient>0.0 0.0 0.0 1.0</ambient>
        <diffuse>0.2 0.2 0.2 1.0</diffuse>
        <specular>0.508273 0.508273 0.508273 1.0</specular>
        <emissive>0.0 0.0 0.0 0.0</emissive>
      </material>
    </visual>
  </gazebo>
  <gazebo reference="robot_battery_link">
    <visual>
      <material>
        <ambient>0.0 0.0 0.0 1.0</ambient>
        <diffuse>0.2 0.2 0.2 1.0</diffuse>
        <specular>0.508273 0.508273 0.508273 1.0</specular>
        <emissive>0.0 0.0 0.0 0.0</emissive>
      </material>
    </visual>
  </gazebo>
  <gazebo reference="robot_contactors_link">
    <visual>
      <material>
        <ambient>0.7 0.3 0.0 1.0</ambient>
        <diffuse>0.7 0.3 0.0 1.0</diffuse>
        <specular>0.7 0.3 0.0 1.0</specular>
        <emissive>0.0 0.0 0.0 0.0</emissive>
      </material>
    </visual>
  </gazebo>
  <gazebo reference="robot_base_logos_link">
    <visual>
      <material>
        <ambient>1.0 0.0 0.0 1.0</ambient>
        <diffuse>0.50754 0.50754 0.50754 1.0</diffuse>
        <specular>0.508273 0.508273 0.508273 1.0</specular>
        <emissive>0.0 0.0 0.0 0.0</emissive>
      </material>
    </visual>
  </gazebo>
  <gazebo reference="robot_leds_link">
    <visual>
      <material>
        <ambient>0.0 1.0 0.0 1.0</ambient>
        <diffuse>0.0 1.0 0.0 1.0</diffuse>
        <specular>0.0 1.0 0.0 1.0</specular>
        <emissive>0.0 0.0 0.0 0.0</emissive>
      </material>
    </visual>
  </gazebo>
  <!--MOTOR WHEEL -->
  <joint name="robot_front_right_motor_wheel_joint" type="revolute">
    <parent link="robot_base_link"/>
    <child link="robot_front_right_motor_wheel"/>
    <origin rpy="0 0 0" xyz="0.4795 -0.2925 0.0"/>
    <axis rpy="0 0 0" xyz="0 0 1"/>
    <!-- limit effort="${steer_joint_effort_limit}" velocity="${steer_joint_velocity_limit}" lower="-1.5708" upper="1.5708" / -->
    <limit effort="100.0" lower="-3.00" upper="3.00" velocity="2.83"/>
    <joint_properties damping="2.0" friction="1.0"/>
  </joint>
  <transmission name="robot_front_right_motor_wheel_trans">
    <type>transmission_interface/SimpleTransmission</type>
    <joint name="robot_front_right_motor_wheel_joint">
      <hardwareInterface>hardware_interface/PositionJointInterface</hardwareInterface>
    </joint>
    <actuator name="robot_front_right_motor_wheel_motor">
      <hardwareInterface>hardware_interface/PositionActuatorInterface</hardwareInterface>
      <mechanicalReduction>1.0</mechanicalReduction>
    </actuator>
  </transmission>
  <link name="robot_front_right_motor_wheel">
    <visual>
      <origin rpy="0 0 3.141592653589793" xyz="0 0 0"/>
      <geometry>
        <mesh filename="package://rbvogui_description/meshes/wheels/hub_rbvogui_xl.stl"/>
      </geometry>
      <material name="red">
        <color rgba="0.9 0.1 0.1 1"/>
      </material>
    </visual>
    <collision>
      <origin rpy="0 0 3.141592653589793" xyz="0 0 0"/>
      <geometry>
        <mesh filename="package://rbvogui_description/meshes/wheels/hub_rbvogui_xl.stl"/>
      </geometry>
    </collision>
    <inertial>
      <mass value="4"/>
      <origin rpy="0 0 3.141592653589793" xyz="0 0.03 0.1"/>
      <inertia ixx="0.03429166666666667" ixy="0" ixz="0" iyy="0.03429166666666667" iyz="0" izz="0.012250000000000002"/>
    </inertial>
  </link>
  <gazebo reference="robot_front_right_motor_wheel">
    <visual>
      <material>
        <ambient>1.0 0.0 0.0 1.0</ambient>
        <diffuse>0.50754 0.50754 0.50754 1.0</diffuse>
        <specular>0.508273 0.508273 0.508273 1.0</specular>
        <emissive>0.0 0.0 0.0 0.0</emissive>
      </material>
    </visual>
  </gazebo>
  <!-- TODO: check reflect parameter -->
  <!--WHEEL TIRE -->
  <joint name="robot_front_right_wheel_joint" type="continuous">
    <parent link="robot_front_right_motor_wheel"/>
    <child link="robot_front_right_wheel"/>
    <origin rpy="0 0 0" xyz="0 0 0"/>
    <axis rpy="0 0 0" xyz="0 1 0"/>
    <limit effort="1000.0" velocity="2000.0"/>
    <joint_properties damping="0.1" friction="{wheel_joint_friction}"/>
  </joint>
  <transmission name="robot_front_right_wheel_trans">
    <type>transmission_interface/SimpleTransmission</type>
    <joint name="robot_front_right_wheel_joint">
      <hardwareInterface>hardware_interface/VelocityJointInterface</hardwareInterface>
    </joint>
    <actuator name="robot_front_right_wheel_motor">
      <hardwareInterface>hardware_interface/VelocityActuatorInterface</hardwareInterface>
      <mechanicalReduction>1.0</mechanicalReduction>
    </actuator>
  </transmission>
  <link name="robot_front_right_wheel">
    <visual>
      <material name="dark-gray">
        <color rgba="0.25 0.25 0.25 1.0"/>
      </material>
      <origin rpy="0 0 3.141592653589793" xyz="0 0 0"/>
      <geometry>
        <mesh filename="package://rbvogui_description/meshes/wheels/wheel_285mm.stl"/>
      </geometry>
      <material name="black_wheel">
        <color rgba="0.1 0.1 0.1 1"/>
      </material>
    </visual>
    <collision>
      <origin rpy="1.5707963267948966 0 0" xyz="0 0 0"/>
      <geometry>
        <sphere radius="0.1425"/>
      </geometry>
    </collision>
    <inertial>
      <mass value="4.0"/>
      <origin rpy="0 1.5707963267948966 1.5707963267948966" xyz="0 0 0"/>
      <inertia ixx="0.026839583333333333" ixy="0" ixz="0" iyy="0.026839583333333333" iyz="0" izz="0.040612499999999996"/>
    </inertial>
  </link>
  <gazebo reference="robot_front_right_wheel">
    <mu1 value="1.0"/>
    <mu2 value="1.0"/>
    <kp value="10000000.0"/>
    <kd value="1.0"/>
    <visual>
      <material>
        <ambient>0.1 0.1 0.1 1.0</ambient>
        <diffuse>0.250754 0.250754 0.250754 1.0</diffuse>
        <specular>0.2508273 0.2508273 0.2508273 1.0</specular>
        <emissive>0.0 0.0 0.0 0.0</emissive>
      </material>
    </visual>
  </gazebo>
  <gazebo reference="robot_front_right_motor_wheel">
    <visual>
      <material>
        <ambient>1.0 0.0 0.0 1.0</ambient>
        <diffuse>0.50754 0.50754 0.50754 1.0</diffuse>
        <specular>0.508273 0.508273 0.508273 1.0</specular>
        <emissive>0.0 0.0 0.0 0.0</emissive>
      </material>
    </visual>
  </gazebo>
  <!--MOTOR WHEEL -->
  <joint name="robot_front_left_motor_wheel_joint" type="revolute">
    <parent link="robot_base_link"/>
    <child link="robot_front_left_motor_wheel"/>
    <origin rpy="0 0 0" xyz="0.4795 0.2925 0.0"/>
    <axis rpy="0 0 0" xyz="0 0 1"/>
    <!-- limit effort="${steer_joint_effort_limit}" velocity="${steer_joint_velocity_limit}" lower="-1.5708" upper="1.5708" / -->
    <limit effort="100.0" lower="-3.00" upper="3.00" velocity="2.83"/>
    <joint_properties damping="2.0" friction="1.0"/>
  </joint>
  <transmission name="robot_front_left_motor_wheel_trans">
    <type>transmission_interface/SimpleTransmission</type>
    <joint name="robot_front_left_motor_wheel_joint">
      <hardwareInterface>hardware_interface/PositionJointInterface</hardwareInterface>
    </joint>
    <actuator name="robot_front_left_motor_wheel_motor">
      <hardwareInterface>hardware_interface/PositionActuatorInterface</hardwareInterface>
      <mechanicalReduction>1.0</mechanicalReduction>
    </actuator>
  </transmission>
  <link name="robot_front_left_motor_wheel">
    <visual>
      <origin rpy="0 0 0" xyz="0 0 0.0"/>
      <geometry>
        <mesh filename="package://rbvogui_description/meshes/wheels/hub_rbvogui_xl.stl"/>
      </geometry>
      <material name="red">
        <color rgba="0.9 0.1 0.1 1"/>
      </material>
    </visual>
    <collision>
      <origin rpy="0 0 0" xyz="0 0 0.0"/>
      <geometry>
        <mesh filename="package://rbvogui_description/meshes/wheels/hub_rbvogui_xl.stl"/>
      </geometry>
    </collision>
    <inertial>
      <mass value="4"/>
      <origin rpy="0 0 0" xyz="0 -0.03 0.1"/>
      <inertia ixx="0.03429166666666667" ixy="0" ixz="0" iyy="0.03429166666666667" iyz="0" izz="0.012250000000000002"/>
    </inertial>
  </link>
  <gazebo reference="robot_front_left_motor_wheel">
    <visual>
      <material>
        <ambient>1.0 0.0 0.0 1.0</ambient>
        <diffuse>0.50754 0.50754 0.50754 1.0</diffuse>
        <specular>0.508273 0.508273 0.508273 1.0</specular>
        <emissive>0.0 0.0 0.0 0.0</emissive>
      </material>
    </visual>
  </gazebo>
  <!-- TODO: check reflect parameter -->
  <!--WHEEL TIRE -->
  <joint name="robot_front_left_wheel_joint" type="continuous">
    <parent link="robot_front_left_motor_wheel"/>
    <child link="robot_front_left_wheel"/>
    <origin rpy="0 0 0" xyz="0 0 0"/>
    <axis rpy="0 0 0" xyz="0 1 0"/>
    <limit effort="1000.0" velocity="2000.0"/>
    <joint_properties damping="0.1" friction="{wheel_joint_friction}"/>
  </joint>
  <transmission name="robot_front_left_wheel_trans">
    <type>transmission_interface/SimpleTransmission</type>
    <joint name="robot_front_left_wheel_joint">
      <hardwareInterface>hardware_interface/VelocityJointInterface</hardwareInterface>
    </joint>
    <actuator name="robot_front_left_wheel_motor">
      <hardwareInterface>hardware_interface/VelocityActuatorInterface</hardwareInterface>
      <mechanicalReduction>1.0</mechanicalReduction>
    </actuator>
  </transmission>
  <link name="robot_front_left_wheel">
    <visual>
      <material name="dark-gray">
        <color rgba="0.25 0.25 0.25 1.0"/>
      </material>
      <origin rpy="0 0 0" xyz="0 0 0"/>
      <geometry>
        <mesh filename="package://rbvogui_description/meshes/wheels/wheel_285mm.stl"/>
      </geometry>
      <material name="black_wheel">
        <color rgba="0.1 0.1 0.1 1"/>
      </material>
    </visual>
    <collision>
      <origin rpy="1.5707963267948966 0 0" xyz="0 0 0"/>
      <geometry>
        <sphere radius="0.1425"/>
      </geometry>
    </collision>
    <inertial>
      <mass value="4.0"/>
      <origin rpy="0 1.5707963267948966 1.5707963267948966" xyz="0 0 0"/>
      <inertia ixx="0.026839583333333333" ixy="0" ixz="0" iyy="0.026839583333333333" iyz="0" izz="0.040612499999999996"/>
    </inertial>
  </link>
  <gazebo reference="robot_front_left_wheel">
    <mu1 value="1.0"/>
    <mu2 value="1.0"/>
    <kp value="10000000.0"/>
    <kd value="1.0"/>
    <visual>
      <material>
        <ambient>0.1 0.1 0.1 1.0</ambient>
        <diffuse>0.250754 0.250754 0.250754 1.0</diffuse>
        <specular>0.2508273 0.2508273 0.2508273 1.0</specular>
        <emissive>0.0 0.0 0.0 0.0</emissive>
      </material>
    </visual>
  </gazebo>
  <gazebo reference="robot_front_left_motor_wheel">
    <visual>
      <material>
        <ambient>1.0 0.0 0.0 1.0</ambient>
        <diffuse>0.50754 0.50754 0.50754 1.0</diffuse>
        <specular>0.508273 0.508273 0.508273 1.0</specular>
        <emissive>0.0 0.0 0.0 0.0</emissive>
      </material>
    </visual>
  </gazebo>
  <!--MOTOR WHEEL -->
  <joint name="robot_back_left_motor_wheel_joint" type="revolute">
    <parent link="robot_base_link"/>
    <child link="robot_back_left_motor_wheel"/>
    <origin rpy="0 0 0" xyz="-0.4795 0.2925 0.0"/>
    <axis rpy="0 0 0" xyz="0 0 1"/>
    <!-- limit effort="${steer_joint_effort_limit}" velocity="${steer_joint_velocity_limit}" lower="-1.5708" upper="1.5708" / -->
    <limit effort="100.0" lower="-3.00" upper="3.00" velocity="2.83"/>
    <joint_properties damping="2.0" friction="1.0"/>
  </joint>
  <transmission name="robot_back_left_motor_wheel_trans">
    <type>transmission_interface/SimpleTransmission</type>
    <joint name="robot_back_left_motor_wheel_joint">
      <hardwareInterface>hardware_interface/PositionJointInterface</hardwareInterface>
    </joint>
    <actuator name="robot_back_left_motor_wheel_motor">
      <hardwareInterface>hardware_interface/PositionActuatorInterface</hardwareInterface>
      <mechanicalReduction>1.0</mechanicalReduction>
    </actuator>
  </transmission>
  <link name="robot_back_left_motor_wheel">
    <visual>
      <origin rpy="0 0 0" xyz="0 0 0.0"/>
      <geometry>
        <mesh filename="package://rbvogui_description/meshes/wheels/hub_rbvogui_xl.stl"/>
      </geometry>
      <material name="red">
        <color rgba="0.9 0.1 0.1 1"/>
      </material>
    </visual>
    <collision>
      <origin rpy="0 0 0" xyz="0 0 0.0"/>
      <geometry>
        <mesh filename="package://rbvogui_description/meshes/wheels/hub_rbvogui_xl.stl"/>
      </geometry>
    </collision>
    <inertial>
      <mass value="4"/>
      <origin rpy="0 0 0" xyz="0 -0.03 0.1"/>
      <inertia ixx="0.03429166666666667" ixy="0" ixz="0" iyy="0.03429166666666667" iyz="0" izz="0.012250000000000002"/>
    </inertial>
  </link>
  <gazebo reference="robot_back_left_motor_wheel">
    <visual>
      <material>
        <ambient>1.0 0.0 0.0 1.0</ambient>
        <diffuse>0.50754 0.50754 0.50754 1.0</diffuse>
        <specular>0.508273 0.508273 0.508273 1.0</specular>
        <emissive>0.0 0.0 0.0 0.0</emissive>
      </material>
    </visual>
  </gazebo>
  <!-- TODO: check reflect parameter -->
  <!--WHEEL TIRE -->
  <joint name="robot_back_left_wheel_joint" type="continuous">
    <parent link="robot_back_left_motor_wheel"/>
    <child link="robot_back_left_wheel"/>
    <origin rpy="0 0 0" xyz="0 0 0"/>
    <axis rpy="0 0 0" xyz="0 1 0"/>
    <limit effort="1000.0" velocity="2000.0"/>
    <joint_properties damping="0.1" friction="{wheel_joint_friction}"/>
  </joint>
  <transmission name="robot_back_left_wheel_trans">
    <type>transmission_interface/SimpleTransmission</type>
    <joint name="robot_back_left_wheel_joint">
      <hardwareInterface>hardware_interface/VelocityJointInterface</hardwareInterface>
    </joint>
    <actuator name="robot_back_left_wheel_motor">
      <hardwareInterface>hardware_interface/VelocityActuatorInterface</hardwareInterface>
      <mechanicalReduction>1.0</mechanicalReduction>
    </actuator>
  </transmission>
  <link name="robot_back_left_wheel">
    <visual>
      <material name="dark-gray">
        <color rgba="0.25 0.25 0.25 1.0"/>
      </material>
      <origin rpy="0 0 0" xyz="0 0 0"/>
      <geometry>
        <mesh filename="package://rbvogui_description/meshes/wheels/wheel_285mm.stl"/>
      </geometry>
      <material name="black_wheel">
        <color rgba="0.1 0.1 0.1 1"/>
      </material>
    </visual>
    <collision>
      <origin rpy="1.5707963267948966 0 0" xyz="0 0 0"/>
      <geometry>
        <sphere radius="0.1425"/>
      </geometry>
    </collision>
    <inertial>
      <mass value="4.0"/>
      <origin rpy="0 1.5707963267948966 1.5707963267948966" xyz="0 0 0"/>
      <inertia ixx="0.026839583333333333" ixy="0" ixz="0" iyy="0.026839583333333333" iyz="0" izz="0.040612499999999996"/>
    </inertial>
  </link>
  <gazebo reference="robot_back_left_wheel">
    <mu1 value="1.0"/>
    <mu2 value="1.0"/>
    <kp value="10000000.0"/>
    <kd value="1.0"/>
    <visual>
      <material>
        <ambient>0.1 0.1 0.1 1.0</ambient>
        <diffuse>0.250754 0.250754 0.250754 1.0</diffuse>
        <specular>0.2508273 0.2508273 0.2508273 1.0</specular>
        <emissive>0.0 0.0 0.0 0.0</emissive>
      </material>
    </visual>
  </gazebo>
  <gazebo reference="robot_back_left_motor_wheel">
    <visual>
      <material>
        <ambient>1.0 0.0 0.0 1.0</ambient>
        <diffuse>0.50754 0.50754 0.50754 1.0</diffuse>
        <specular>0.508273 0.508273 0.508273 1.0</specular>
        <emissive>0.0 0.0 0.0 0.0</emissive>
      </material>
    </visual>
  </gazebo>
  <!--MOTOR WHEEL -->
  <joint name="robot_back_right_motor_wheel_joint" type="revolute">
    <parent link="robot_base_link"/>
    <child link="robot_back_right_motor_wheel"/>
    <origin rpy="0 0 0" xyz="-0.4795 -0.2925 0.0"/>
    <axis rpy="0 0 0" xyz="0 0 1"/>
    <!-- limit effort="${steer_joint_effort_limit}" velocity="${steer_joint_velocity_limit}" lower="-1.5708" upper="1.5708" / -->
    <limit effort="100.0" lower="-3.00" upper="3.00" velocity="2.83"/>
    <joint_properties damping="2.0" friction="1.0"/>
  </joint>
  <transmission name="robot_back_right_motor_wheel_trans">
    <type>transmission_interface/SimpleTransmission</type>
    <joint name="robot_back_right_motor_wheel_joint">
      <hardwareInterface>hardware_interface/PositionJointInterface</hardwareInterface>
    </joint>
    <actuator name="robot_back_right_motor_wheel_motor">
      <hardwareInterface>hardware_interface/PositionActuatorInterface</hardwareInterface>
      <mechanicalReduction>1.0</mechanicalReduction>
    </actuator>
  </transmission>
  <link name="robot_back_right_motor_wheel">
    <visual>
      <origin rpy="0 0 3.141592653589793" xyz="0 0 0"/>
      <geometry>
        <mesh filename="package://rbvogui_description/meshes/wheels/hub_rbvogui_xl.stl"/>
      </geometry>
      <material name="red">
        <color rgba="0.9 0.1 0.1 1"/>
      </material>
    </visual>
    <collision>
      <origin rpy="0 0 3.141592653589793" xyz="0 0 0"/>
      <geometry>
        <mesh filename="package://rbvogui_description/meshes/wheels/hub_rbvogui_xl.stl"/>
      </geometry>
    </collision>
    <inertial>
      <mass value="4"/>
      <origin rpy="0 0 3.141592653589793" xyz="0 0.03 0.1"/>
      <inertia ixx="0.03429166666666667" ixy="0" ixz="0" iyy="0.03429166666666667" iyz="0" izz="0.012250000000000002"/>
    </inertial>
  </link>
  <gazebo reference="robot_back_right_motor_wheel">
    <visual>
      <material>
        <ambient>1.0 0.0 0.0 1.0</ambient>
        <diffuse>0.50754 0.50754 0.50754 1.0</diffuse>
        <specular>0.508273 0.508273 0.508273 1.0</specular>
        <emissive>0.0 0.0 0.0 0.0</emissive>
      </material>
    </visual>
  </gazebo>
  <!-- TODO: check reflect parameter -->
  <!--WHEEL TIRE -->
  <joint name="robot_back_right_wheel_joint" type="continuous">
    <parent link="robot_back_right_motor_wheel"/>
    <child link="robot_back_right_wheel"/>
    <origin rpy="0 0 0" xyz="0 0 0"/>
    <axis rpy="0 0 0" xyz="0 1 0"/>
    <limit effort="1000.0" velocity="2000.0"/>
    <joint_properties damping="0.1" friction="{wheel_joint_friction}"/>
  </joint>
  <transmission name="robot_back_right_wheel_trans">
    <type>transmission_interface/SimpleTransmission</type>
    <joint name="robot_back_right_wheel_joint">
      <hardwareInterface>hardware_interface/VelocityJointInterface</hardwareInterface>
    </joint>
    <actuator name="robot_back_right_wheel_motor">
      <hardwareInterface>hardware_interface/VelocityActuatorInterface</hardwareInterface>
      <mechanicalReduction>1.0</mechanicalReduction>
    </actuator>
  </transmission>
  <link name="robot_back_right_wheel">
    <visual>
      <material name="dark-gray">
        <color rgba="0.25 0.25 0.25 1.0"/>
      </material>
      <origin rpy="0 0 3.141592653589793" xyz="0 0 0"/>
      <geometry>
        <mesh filename="package://rbvogui_description/meshes/wheels/wheel_285mm.stl"/>
      </geometry>
      <material name="black_wheel">
        <color rgba="0.1 0.1 0.1 1"/>
      </material>
    </visual>
    <collision>
      <origin rpy="1.5707963267948966 0 0" xyz="0 0 0"/>
      <geometry>
        <sphere radius="0.1425"/>
      </geometry>
    </collision>
    <inertial>
      <mass value="4.0"/>
      <origin rpy="0 1.5707963267948966 1.5707963267948966" xyz="0 0 0"/>
      <inertia ixx="0.026839583333333333" ixy="0" ixz="0" iyy="0.026839583333333333" iyz="0" izz="0.040612499999999996"/>
    </inertial>
  </link>
  <gazebo reference="robot_back_right_wheel">
    <mu1 value="1.0"/>
    <mu2 value="1.0"/>
    <kp value="10000000.0"/>
    <kd value="1.0"/>
    <visual>
      <material>
        <ambient>0.1 0.1 0.1 1.0</ambient>
        <diffuse>0.250754 0.250754 0.250754 1.0</diffuse>
        <specular>0.2508273 0.2508273 0.2508273 1.0</specular>
        <emissive>0.0 0.0 0.0 0.0</emissive>
      </material>
    </visual>
  </gazebo>
  <gazebo reference="robot_back_right_motor_wheel">
    <visual>
      <material>
        <ambient>1.0 0.0 0.0 1.0</ambient>
        <diffuse>0.50754 0.50754 0.50754 1.0</diffuse>
        <specular>0.508273 0.508273 0.508273 1.0</specular>
        <emissive>0.0 0.0 0.0 0.0</emissive>
      </material>
    </visual>
  </gazebo>
  <!-- SENSORS see robotnik_sensors for the specific configuration -->
  <joint name="robot_imu_base_joint" type="fixed">
    <axis xyz="1 0 0"/>
    <!--origin xyz="0 0 0.2825"/-->
    <origin rpy="0 0 0" xyz="0.3 -0.3 0.0725"/>
    <parent link="robot_chassis_link"/>
    <child link="robot_imu_base_link"/>
  </joint>
  <link name="robot_imu_base_link">
    <inertial>
      <origin rpy="0 0 0" xyz="0.0 0 0.01"/>
      <mass value="0.05"/>
      <inertia ixx="3.3333333333333337e-06" ixy="0" ixz="0" iyy="3.3333333333333337e-06" iyz="0" izz="3.3333333333333337e-06"/>
    </inertial>
    <visual>
      <origin rpy="0 0 0" xyz="0 0 0"/>
      <material name="vectornav_imu_color">
        <color rgba="1 0 0 1"/>
      </material>
      <geometry>
        <mesh filename="package://robotnik_sensors/meshes/vectornav_vn100.stl"/>
      </geometry>
    </visual>
    <collision>
      <origin rpy="0 0 0" xyz="0 0 0.0045"/>
      <geometry>
        <box size="0.036 0.037 0.009"/>
      </geometry>
    </collision>
  </link>
  <joint name="robot_imu_joint" type="fixed">
    <axis xyz="1 0 0"/>
    <origin xyz="0.00671 0.0047 0.0059"/>
    <parent link="robot_imu_base_link"/>
    <child link="robot_imu_link"/>
  </joint>
  <link name="robot_imu_link">
	  </link>
  <gazebo reference="robot_imu_base_link">
    <material>Gazebo/Red</material>
  </gazebo>
  <gazebo>
    <plugin filename="libhector_gazebo_ros_imu.so" name="robot_imu_controller">
      <alwaysOn>true</alwaysOn>
      <topicName>imu/data</topicName>
      <serviceName>robot_imuimu/service</serviceName>
      <bodyName>robot_imu_link</bodyName>
      <frameId>robot_imu_link</frameId>
      <updateRate>50.0</updateRate>
      <gaussianNoise>0.00</gaussianNoise>
      <yawOffset>0.0</yawOffset>
      <yawDrift>0.0</yawDrift>
      <yawGaussianNoise>0.0</yawGaussianNoise>
      <!-- angular velocities parameters -->
      <rateOffset>0.0 0.0 0.0</rateOffset>
      <rateDrift>0.0 0.0 0.0</rateDrift>
      <rateGaussianNoise>0.0 0.0 0.0</rateGaussianNoise>
      <!-- linear accelerations parameters -->
      <accelOffset>0.0 0.0 0.0</accelOffset>
      <accelDrift>0.0 0.0 0.0</accelDrift>
      <accelGaussianNoise>0.0 0.0 0.0</accelGaussianNoise>
    </plugin>
  </gazebo>
  <!-- ANTENNA GPS -->
  <joint name="robot_gps_joint" type="fixed">
    <axis xyz="0 1 0"/>
    <origin rpy="0 0 0" xyz="-0.472 0.40028 0.44044"/>
    <parent link="robot_chassis_link"/>
    <child link="robot_gps_base_link"/>
  </joint>
  <link name="robot_gps_base_link">
    <inertial>
      <origin rpy="0 0 0" xyz="0.0 0 0.015"/>
      <mass value="0.2"/>
      <inertia ixx="0.00012435" ixy="0" ixz="0" iyy="0.00012435" iyz="0" izz="0.00021870000000000003"/>
    </inertial>
    <visual>
      <origin rpy="0 0 0" xyz="0 0 0"/>
      <material name="gps_color">
        <color rgba="1 1 1 1"/>
      </material>
      <geometry>
        <mesh filename="package://rbvogui_description/meshes/structures/gps_mast.STL" scale="1.0 1.0 1.0"/>
      </geometry>
    </visual>
    <collision>
      <origin rpy="0 0 0" xyz="0 0 -0.15"/>
      <geometry>
        <cylinder length="0.4" radius="0.05"/>
      </geometry>
    </collision>
  </link>
  <gazebo reference="robot_gps_base_link">
    <material>Gazebo/Black</material>
    <gravity>true</gravity>
  </gazebo>
  <gazebo>
    <plugin filename="libhector_gazebo_ros_gps.so" name="robot_gps_controller">
      <alwaysOn>1</alwaysOn>
      <updateRate>5</updateRate>
      <bodyName>robot_gps_base_link</bodyName>
      <!-- must be the link of the gps device, not the base_link or base_footprint -->
      <frameId>robot_gps_base_link</frameId>
      <topicName>gps/fix</topicName>
      <!-- GPS coordinates -->
      <referenceLatitude>39.5080331</referenceLatitude>
      <referenceLongitude>-0.4619816</referenceLongitude>
      <!-- To set heading in ENU orientation (degrees) -->
      <referenceHeading>90</referenceHeading>
      <velocityTopicName>gps/fix_velocity</velocityTopicName>
      <drift>0.0 0.0 0.0</drift>
      <!--<drift>0.0001 0.0001 0.0001</drift>-->
      <!--<drift>0.3 0.3 0.3</drift>-->
      <gaussianNoise>0.00001 0.00001 0.00001</gaussianNoise>
      <!--<gaussianNoise>0.00001 0.00001 0.00001</gaussianNoise>-->
      <velocityDrift>0.00001 0.00001 0.00001</velocityDrift>
      <!--<velocityGaussianNoise>0.1 0.1 0.1</velocityGaussianNoise>-->
      <velocityGaussianNoise>0.00001 0.00001 0.00001</velocityGaussianNoise>
    </plugin>
  </gazebo>
  <joint name="robot_front_rgbd_camera_joint" type="fixed">
    <origin rpy="0 0 0" xyz="0.637 0.0 -0.036"/>
    <parent link="robot_chassis_link"/>
    <child link="robot_front_rgbd_camera_link"/>
  </joint>
  <link name="robot_front_rgbd_camera_link">
    <visual>
      <origin rpy="0 0 0" xyz="0 0 0"/>
      <geometry>
        <mesh filename="package://robotnik_sensors/meshes/orbbec_astra.dae"/>
      </geometry>
    </visual>
    <collision>
      <geometry>
        <mesh filename="package://robotnik_sensors/meshes/orbbec_astra.dae"/>
      </geometry>
    </collision>
    <inertial>
      <mass value="0.001"/>
      <origin xyz="0.0 0.0 0.0"/>
      <inertia ixx="2.3437500000000006e-06" ixy="0" ixz="0" iyy="2.0833333333333336e-07" iyz="0" izz="2.4020833333333336e-06"/>
    </inertial>
  </link>
  <joint name="robot_front_rgbd_camera_rgb_joint" type="fixed">
    <origin rpy="0.0 0.0 0.0" xyz="0.0 0.0125 0.0150"/>
    <parent link="robot_front_rgbd_camera_link"/>
    <child link="robot_front_rgbd_camera_rgb_frame"/>
  </joint>
  <link name="robot_front_rgbd_camera_rgb_frame">
    <inertial>
      <mass value="0.297"/>
      <origin xyz="-0.02 -0.0125 0.0"/>
      <inertia ixx="0.0006960937500000001" ixy="0" ixz="0" iyy="6.1875e-05" iyz="0" izz="0.00071341875"/>
    </inertial>
  </link>
  <joint name="robot_front_rgbd_camera_rgb_optical_joint" type="fixed">
    <origin rpy="-1.5707963267948966 0 -1.5707963267948966" xyz="0.0 0.0 0.0"/>
    <parent link="robot_front_rgbd_camera_rgb_frame"/>
    <child link="robot_front_rgbd_camera_rgb_optical_frame"/>
  </joint>
  <link name="robot_front_rgbd_camera_rgb_optical_frame">
    <inertial>
      <mass value="0.001"/>
      <origin rpy="1.5707963267948966 0 1.5707963267948966" xyz="0 0 0"/>
      <inertia ixx="2.3437500000000006e-06" ixy="0" ixz="0" iyy="2.0833333333333336e-07" iyz="0" izz="2.4020833333333336e-06"/>
    </inertial>
  </link>
  <joint name="robot_front_rgbd_camera_depth_joint" type="fixed">
    <origin rpy="0 0 0" xyz="0.0 0.0375 0.0150"/>
    <parent link="robot_front_rgbd_camera_link"/>
    <child link="robot_front_rgbd_camera_depth_frame"/>
  </joint>
  <link name="robot_front_rgbd_camera_depth_frame">
    <inertial>
      <mass value="0.001"/>
      <origin xyz="0 0 0"/>
      <inertia ixx="2.3437500000000006e-06" ixy="0" ixz="0" iyy="2.0833333333333336e-07" iyz="0" izz="2.4020833333333336e-06"/>
    </inertial>
  </link>
  <joint name="robot_front_rgbd_camera_depth_optical_joint" type="fixed">
    <origin rpy="-1.5707963267948966 0 -1.5707963267948966" xyz="0 0 0"/>
    <parent link="robot_front_rgbd_camera_depth_frame"/>
    <child link="robot_front_rgbd_camera_depth_optical_frame"/>
  </joint>
  <link name="robot_front_rgbd_camera_depth_optical_frame">
    <inertial>
      <mass value="0.001"/>
      <origin xyz="0 0 0"/>
      <inertia ixx="2.3437500000000006e-06" ixy="0" ixz="0" iyy="2.0833333333333336e-07" iyz="0" izz="2.4020833333333336e-06"/>
    </inertial>
  </link>
  <gazebo reference="robot_front_rgbd_camera_link">
    <sensor name="robot_front_rgbd_camera_depth_sensor" type="depth">
      <always_on>true</always_on>
      <update_rate>20.0</update_rate>
      <camera>
        <horizontal_fov>1.0471975511965976</horizontal_fov>
        <image>
          <format>R8G8B8</format>
          <width>640</width>
          <height>480</height>
        </image>
        <clip>
          <near>0.05</near>
          <far>3.5</far>
        </clip>
      </camera>
      <plugin filename="libgazebo_ros_openni_kinect.so" name="robot_front_rgbd_camera_controller">
        <cameraName>front_rgbd_camera</cameraName>
        <alwaysOn>true</alwaysOn>
        <updateRate>10</updateRate>
        <imageTopicName>rgb/image_raw</imageTopicName>
        <depthImageTopicName>depth/image_raw</depthImageTopicName>
        <pointCloudTopicName>depth/points</pointCloudTopicName>
        <cameraInfoTopicName>rgb/camera_info</cameraInfoTopicName>
        <depthImageCameraInfoTopicName>depth/camera_info</depthImageCameraInfoTopicName>
        <frameName>/robot_front_rgbd_camera_depth_optical_frame</frameName>
        <baseline>0.1</baseline>
        <distortion_k1>0.0</distortion_k1>
        <distortion_k2>0.0</distortion_k2>
        <distortion_k3>0.0</distortion_k3>
        <distortion_t1>0.0</distortion_t1>
        <distortion_t2>0.0</distortion_t2>
        <pointCloudCutoff>0.4</pointCloudCutoff>
      </plugin>
    </sensor>
  </gazebo>
  <!-- Zed camera
        <xacro:sensor_zed prefix="${prefix}zed" parent="${prefix}chassis_link" model="zed2">
            <origin xyz="0.63658 0.0 -0.03643" rpy="0 0 0"/>
        </xacro:sensor_zed>
        -->
  <joint name="robot_sick_front_supportsick_support_joint" type="fixed">
    <parent link="robot_chassis_link"/>
    <child link="robot_sick_front_supportsick_support_link"/>
    <origin rpy="0 1.5707963267948966 1.5707963267948966" xyz="0.472 0.3795 0.09788"/>
  </joint>
  <link name="robot_sick_front_supportsick_support_link">
    <visual>
      <origin rpy="0 0 1.5707963267948966" xyz="0.0 0.0 0.0"/>
      <geometry>
        <mesh filename="package://rbvogui_description/meshes/structures/sick_structure.stl"/>
      </geometry>
      <material name="red">
        <color rgba="0.9 0.1 0.1 1"/>
      </material>
    </visual>
    <collision>
      <origin rpy="0 0 1.5707963267948966" xyz="0 0 0"/>
      <geometry>
        <box size="0.001 0.001 0.001"/>
      </geometry>
      <material name="red">
        <color rgba="0.9 0.1 0.1 1"/>
      </material>
    </collision>
    <inertial>
      <mass value="5"/>
      <origin rpy="0 0 1.5707963267948966" xyz="0 0 0"/>
      <inertia ixx="0.08333333333333336" ixy="0" ixz="0" iyy="0.08333333333333336" iyz="0" izz="0.13333333333333336"/>
    </inertial>
  </link>
  <gazebo reference="robot_sick_front_supportsick_support_link">
    <material>Gazebo/Red</material>
    <visual>
      <material>
        <ambient>1.0 0.0 0.0 1.0</ambient>
        <diffuse>0.52 0.2 0.2 1.0</diffuse>
        <specular>0.508273 0.508273 0.508273 1.0</specular>
        <emissive>0.0 0.0 0.0 0.0</emissive>
      </material>
    </visual>
  </gazebo>
  <joint name="robot_sick_rear_supportsick_support_joint" type="fixed">
    <parent link="robot_chassis_link"/>
    <child link="robot_sick_rear_supportsick_support_link"/>
    <origin rpy="0 1.5707963267948966 -1.5707963267948966" xyz="-0.472 -0.3795 0.09788"/>
  </joint>
  <link name="robot_sick_rear_supportsick_support_link">
    <visual>
      <origin rpy="0 0 1.5707963267948966" xyz="0.0 0.0 0.0"/>
      <geometry>
        <mesh filename="package://rbvogui_description/meshes/structures/sick_structure.stl"/>
      </geometry>
      <material name="red">
        <color rgba="0.9 0.1 0.1 1"/>
      </material>
    </visual>
    <collision>
      <origin rpy="0 0 1.5707963267948966" xyz="0 0 0"/>
      <geometry>
        <box size="0.001 0.001 0.001"/>
      </geometry>
      <material name="red">
        <color rgba="0.9 0.1 0.1 1"/>
      </material>
    </collision>
    <inertial>
      <mass value="5"/>
      <origin rpy="0 0 1.5707963267948966" xyz="0 0 0"/>
      <inertia ixx="0.08333333333333336" ixy="0" ixz="0" iyy="0.08333333333333336" iyz="0" izz="0.13333333333333336"/>
    </inertial>
  </link>
  <gazebo reference="robot_sick_rear_supportsick_support_link">
    <material>Gazebo/Red</material>
    <visual>
      <material>
        <ambient>1.0 0.0 0.0 1.0</ambient>
        <diffuse>0.52 0.2 0.2 1.0</diffuse>
        <specular>0.508273 0.508273 0.508273 1.0</specular>
        <emissive>0.0 0.0 0.0 0.0</emissive>
      </material>
    </visual>
  </gazebo>
  <joint name="robot_sick_front_protectorsick_support_joint" type="fixed">
    <parent link="robot_chassis_link"/>
    <child link="robot_sick_front_protectorsick_support_link"/>
    <origin rpy="0 0 -0.7853981633974483" xyz="0.64542 0.39594 0.11073"/>
  </joint>
  <link name="robot_sick_front_protectorsick_support_link">
    <visual>
      <origin rpy="0 0 1.5707963267948966" xyz="0.0 0.0 0.0"/>
      <geometry>
        <mesh filename="package://rbvogui_description/meshes/structures/sick_protector.stl"/>
      </geometry>
      <material name="black">
        <color rgba="0.1 0.1 0.1 1"/>
      </material>
    </visual>
    <collision>
      <origin rpy="0 0 1.5707963267948966" xyz="0 0 0"/>
      <geometry>
        <box size="0.001 0.001 0.001"/>
      </geometry>
      <material name="black">
        <color rgba="1.0 1.0 1.0 1"/>
      </material>
    </collision>
    <inertial>
      <mass value="5"/>
      <origin rpy="0 0 1.5707963267948966" xyz="0 0 0"/>
      <inertia ixx="0.08333333333333336" ixy="0" ixz="0" iyy="0.08333333333333336" iyz="0" izz="0.13333333333333336"/>
    </inertial>
  </link>
  <gazebo reference="robot_sick_front_protectorsick_support_link">
    <material>Gazebo/Black</material>
    <visual>
      <material>
        <ambient>0.1 0.1 0.1 1.0</ambient>
        <diffuse>0.2 0.2 0.2 1.0</diffuse>
        <specular>0.508273 0.508273 0.508273 1.0</specular>
        <emissive>0.0 0.0 0.0 0.0</emissive>
      </material>
    </visual>
  </gazebo>
  <joint name="robot_sick_rear_protectorsick_support_joint" type="fixed">
    <parent link="robot_chassis_link"/>
    <child link="robot_sick_rear_protectorsick_support_link"/>
    <origin rpy="0 0 2.356194490192345" xyz="-0.64542 -0.39594 0.11073"/>
  </joint>
  <link name="robot_sick_rear_protectorsick_support_link">
    <visual>
      <origin rpy="0 0 1.5707963267948966" xyz="0.0 0.0 0.0"/>
      <geometry>
        <mesh filename="package://rbvogui_description/meshes/structures/sick_protector.stl"/>
      </geometry>
      <material name="black">
        <color rgba="0.1 0.1 0.1 1"/>
      </material>
    </visual>
    <collision>
      <origin rpy="0 0 1.5707963267948966" xyz="0 0 0"/>
      <geometry>
        <box size="0.001 0.001 0.001"/>
      </geometry>
      <material name="black">
        <color rgba="1.0 1.0 1.0 1"/>
      </material>
    </collision>
    <inertial>
      <mass value="5"/>
      <origin rpy="0 0 1.5707963267948966" xyz="0 0 0"/>
      <inertia ixx="0.08333333333333336" ixy="0" ixz="0" iyy="0.08333333333333336" iyz="0" izz="0.13333333333333336"/>
    </inertial>
  </link>
  <gazebo reference="robot_sick_rear_protectorsick_support_link">
    <material>Gazebo/Black</material>
    <visual>
      <material>
        <ambient>0.1 0.1 0.1 1.0</ambient>
        <diffuse>0.2 0.2 0.2 1.0</diffuse>
        <specular>0.508273 0.508273 0.508273 1.0</specular>
        <emissive>0.0 0.0 0.0 0.0</emissive>
      </material>
    </visual>
  </gazebo>
  <joint name="robot_front_laser_base_joint" type="fixed">
    <origin rpy="3.141592653589793 0 0.7853981633974483" xyz="0.64555 0.39595 0.16608"/>
    <parent link="robot_chassis_link"/>
    <child link="robot_front_laser_base_link"/>
  </joint>
  <link name="robot_front_laser_base_link">
    <collision>
      <origin rpy="0 0 0" xyz="0 0 0.075"/>
      <geometry>
        <box size="0.106 0.094 0.152"/>
        <!--<cylinder radius="0.058" length="0.152"/>-->
        <!--<mesh filename="package://robotnik_sensors/meshes/sick_microscan3.dae"/>-->
      </geometry>
    </collision>
    <visual>
      <origin rpy="0 0 0" xyz="0 0 0"/>
      <geometry>
        <mesh filename="package://robotnik_sensors/meshes/sick_microscan3.dae"/>
      </geometry>
    </visual>
    <inertial>
      <mass value="1.15"/>
      <origin rpy="0 0 0" xyz="0 0 0.075"/>
      <inertia ixx="0.0033370124999999996" ixy="0" ixz="0" iyy="0.003358383333333333" iyz="0" izz="0.0023828958333333332"/>
    </inertial>
  </link>
  <joint name="robot_front_laser_joint" type="fixed">
    <parent link="robot_front_laser_base_link"/>
    <child link="robot_front_laser_link"/>
    <origin rpy="0 0 0" xyz="0.0 0 0.110"/>
  </joint>
  <link name="robot_front_laser_link"/>
  <gazebo reference="robot_front_laser_link">
    <sensor name="robot_front_laser_sensor" type="ray">
      <pose>0 0 0 0 0 0</pose>
      <visualize>false</visualize>
      <update_rate>12.5</update_rate>
      <ray>
        <scan>
          <horizontal>
            <samples>541</samples>
            <resolution>1</resolution>
            <min_angle>-2.2465</min_angle>
            <max_angle>2.2465</max_angle>
          </horizontal>
        </scan>
        <range>
          <min>0.10</min>
          <max>30.0</max>
          <resolution>0.03</resolution>
        </range>
        <noise>
          <type>gaussian</type>
          <mean>0.0</mean>
          <stddev>0.03</stddev>
        </noise>
      </ray>
      <plugin filename="libgazebo_ros_laser.so" name="robot_front_laser_controller">
        <topicName>front_laser/scan</topicName>
        <frameName>/robot_front_laser_link</frameName>
        <!-- if not global (leading /) sets the current namespace as a prefix (/ns/name_laser_link) -->
      </plugin>
    </sensor>
  </gazebo>
  <joint name="robot_rear_laser_base_joint" type="fixed">
    <origin rpy="3.141592653589793 0 -2.356194490192345" xyz="-0.64555 -0.39985 0.16608"/>
    <parent link="robot_chassis_link"/>
    <child link="robot_rear_laser_base_link"/>
  </joint>
  <link name="robot_rear_laser_base_link">
    <collision>
      <origin rpy="0 0 0" xyz="0 0 0.075"/>
      <geometry>
        <box size="0.106 0.094 0.152"/>
        <!--<cylinder radius="0.058" length="0.152"/>-->
        <!--<mesh filename="package://robotnik_sensors/meshes/sick_microscan3.dae"/>-->
      </geometry>
    </collision>
    <visual>
      <origin rpy="0 0 0" xyz="0 0 0"/>
      <geometry>
        <mesh filename="package://robotnik_sensors/meshes/sick_microscan3.dae"/>
      </geometry>
    </visual>
    <inertial>
      <mass value="1.15"/>
      <origin rpy="0 0 0" xyz="0 0 0.075"/>
      <inertia ixx="0.0033370124999999996" ixy="0" ixz="0" iyy="0.003358383333333333" iyz="0" izz="0.0023828958333333332"/>
    </inertial>
  </link>
  <joint name="robot_rear_laser_joint" type="fixed">
    <parent link="robot_rear_laser_base_link"/>
    <child link="robot_rear_laser_link"/>
    <origin rpy="0 0 0" xyz="0.0 0 0.110"/>
  </joint>
  <link name="robot_rear_laser_link"/>
  <gazebo reference="robot_rear_laser_link">
    <sensor name="robot_rear_laser_sensor" type="ray">
      <pose>0 0 0 0 0 0</pose>
      <visualize>false</visualize>
      <update_rate>12.5</update_rate>
      <ray>
        <scan>
          <horizontal>
            <samples>541</samples>
            <resolution>1</resolution>
            <min_angle>-2.2465</min_angle>
            <max_angle>2.2465</max_angle>
          </horizontal>
        </scan>
        <range>
          <min>0.10</min>
          <max>30.0</max>
          <resolution>0.03</resolution>
        </range>
        <noise>
          <type>gaussian</type>
          <mean>0.0</mean>
          <stddev>0.03</stddev>
        </noise>
      </ray>
      <plugin filename="libgazebo_ros_laser.so" name="robot_rear_laser_controller">
        <topicName>rear_laser/scan</topicName>
        <frameName>/robot_rear_laser_link</frameName>
        <!-- if not global (leading /) sets the current namespace as a prefix (/ns/name_laser_link) -->
      </plugin>
    </sensor>
  </gazebo>
</robot>
