<?xml version="1.0" encoding="utf-8"?>
<robot
  name="cobod_arm_study">
  <link
    name="Link_1">
    <!--<inertial>
      <origin
        xyz="-3.52E-05 0.00025739 0.18016"
        rpy="0 0 0" />
      <mass
        value="4.7914" />
      <inertia
        ixx="0.010294"
        ixy="-5.0099E-06"
        ixz="-1.4283E-07"
        iyy="0.010294"
        iyz="-5.2258E-08"
        izz="0.014258" />
    </inertial> -->
    <visual>
      <origin
        xyz="0 0 0"
        rpy="0 0 0" />
      <geometry>
        <mesh
          filename="package://cobod_arm_study/meshes/cobod_arm/Link_1.STL" />
      </geometry>
      <material
        name="">
        <color
          rgba="0.0 0.0 0.0 1.0" />
      </material>
    </visual>
    <collision>
      <origin
        xyz="0 0 0"
        rpy="0 0 0" />
      <geometry>
        <mesh
          filename="package://cobod_arm_study/meshes/cobod_arm/Link_1.STL" />
      </geometry>
    </collision>
  </link>
  <link
    name="Link_2">
    <inertial>
      <origin
        xyz="-7.8391E-06 -0.012776 0.12873"
        rpy="0 0 0" />
      <mass
        value="7.3624" />
      <inertia
        ixx="0.033473"
        ixy="1.1353E-07"
        ixz="-3.2631E-07"
        iyy="0.03182"
        iyz="-0.00011331"
        izz="0.038055" />
    </inertial>
    <visual>
      <origin
        xyz="0 0 0"
        rpy="0 0 0" />
      <geometry>
        <mesh
          filename="package://cobod_arm_study/meshes/cobod_arm/Link_2.STL" />
      </geometry>
      <material
        name="">
        <color
          rgba="0.75294 0.75294 0.75294 1" />
      </material>
    </visual>
    <collision>
      <origin
        xyz="0 0 0"
        rpy="0 0 0" />
      <geometry>
        <mesh
          filename="package://cobod_arm_study/meshes/cobod_arm/Link_2.STL" />
      </geometry>
    </collision>
  </link>
  <joint
    name="Joint_1"
    type="revolute">
    <origin
      xyz="0 0 0.3291"
      rpy="0 0 0" />
    <parent
      link="Link_1" />
    <child
      link="Link_2" />
    <axis
      xyz="0 0 1" />
    <limit
      lower="-4.7123889804"
      upper="4.7123889804"
      effort="30"
      velocity="1.0" />
  </joint>
  <link
    name="Link_3">
    <inertial>
      <origin
        xyz="0.235022759253163 -0.00401386645158441 7.21253701049529E-05"
        rpy="0 0 0" />
      <mass
        value="28.6054693520369" />
      <inertia
        ixx="0.224063966841879"
        ixy="-0.000221363650161617"
        ixz="1.88092275157013E-07"
        iyy="0.226262774331348"
        iyz="-0.00021885612747333"
        izz="0.318560163938282" />
    </inertial>
    <visual>
      <origin
        xyz="0 0 0"
        rpy="0 0 0" />
      <geometry>
        <mesh
          filename="package://cobod_arm_study/meshes/cobod_arm/Link_3.STL" />
      </geometry>
      <material
        name="">
        <color
          rgba="0.75294 0.75294 0.75294 1" />
      </material>
    </visual>
    <collision>
      <origin
        xyz="0 0 0"
        rpy="0 0 0" />
      <geometry>
        <mesh
          filename="package://cobod_arm_study/meshes/cobod_arm/Link_3.STL" />
      </geometry>
    </collision>
  </link>
  <joint
    name="Joint_2"
    type="revolute">
    <origin
      xyz="0 0 0.2105"
      rpy="0 0 0" />
    <parent
      link="Link_2" />
    <child
      link="Link_3" />
    <axis
      xyz="0 1 0" />
    <limit
      lower="-1.5707963268"
      upper="0.62"
      effort="10"
      velocity="1.0" />
  </joint>
  <link
    name="Link_4">
    <inertial>
      <origin
        xyz="-1.45908803927952E-08 0.00196725805663702 0.0139826061951497"
        rpy="0 0 0" />
      <mass
        value="10.0735163552972" />
      <inertia
        ixx="0.112605098335051"
        ixy="-4.67417361729634E-08"
        ixz="-5.04848248636358E-10"
        iyy="0.0510066020994643"
        iyz="6.88874166940094E-09"
        izz="0.108968741789178" />
    </inertial>
    <visual>
      <origin
        xyz="0 0 0"
        rpy="0 0 0" />
      <geometry>
        <mesh
          filename="package://cobod_arm_study/meshes/cobod_arm/Link_4.STL" />
      </geometry>
      <material
        name="">
        <color
          rgba="0.75294 0.75294 0.75294 1" />
      </material>
    </visual>
    <collision>
      <origin
        xyz="0 0 0"
        rpy="0 0 0" />
      <geometry>
        <mesh
          filename="package://cobod_arm_study/meshes/cobod_arm/Link_4.STL" />
      </geometry>
    </collision>
  </link>
  <joint
    name="Joint_3"
    type="revolute">
    <origin
      xyz="0.585 0 0"
      rpy="0 0 0" />
    <parent
      link="Link_3" />
    <child
      link="Link_4" />
    <axis
      xyz="0 1 0" />
    <limit
      lower="0.0"
      upper="1.5707963268"
      effort="8"
      velocity="1.0" />
  </joint>
  <link
    name="Link_5">
    <inertial>
      <origin
        xyz="-0.247682444320403 -0.00775545106567575 0.111722543098604"
        rpy="0 0 0" />
      <mass
        value="26.5401875392219" />
      <inertia
        ixx="0.184252998305444"
        ixy="0.000149108099598118"
        ixz="0.0098383773550722"
        iyy="0.220799803084113"
        iyz="0.000218788745845401"
        izz="0.275714676562128" />
    </inertial>
    <visual>
      <origin
        xyz="0 0 0"
        rpy="0 0 0" />
      <geometry>
        <mesh
          filename="package://cobod_arm_study/meshes/cobod_arm/Link_5.STL" />
      </geometry>
      <material
        name="">
        <color
          rgba="0.752941176470588 0.752941176470588 0.752941176470588 1" />
      </material>
    </visual>
    <collision>
      <origin
        xyz="0 0 0"
        rpy="0 0 0" />
      <geometry>
        <mesh
          filename="package://cobod_arm_study/meshes/cobod_arm/Link_5.STL" />
      </geometry>
    </collision>
  </link>
  <joint
    name="Joint_4"
    type="fixed">
    <origin
      xyz="0 0 0.107"
      rpy="0 0 0" />
    <parent
      link="Link_4" />
    <child
      link="Link_5" />
    <axis
      xyz="0 0 0" />
  </joint>
  <link
    name="Link_6">
    <inertial>
      <origin
        xyz="-0.022500253006789 -0.0072895768140177 0.1744358916349"
        rpy="0 0 0" />
      <mass
        value="16.529018462687" />
      <inertia
        ixx="0.168047413371887"
        ixy="-2.34589761332764E-05"
        ixz="8.05477021766983E-10"
        iyy="0.14814978411948"
        iyz="-7.90247161599344E-09"
        izz="0.103973473045969" />
    </inertial>
    <visual>
      <origin
        xyz="0 0 0"
        rpy="0 0 0" />
      <geometry>
        <mesh
          filename="package://cobod_arm_study/meshes/cobod_arm/Link_6.STL" />
      </geometry>
      <material
        name="">
        <color
          rgba="0.75294 0.75294 0.75294 1" />
      </material>
    </visual>
    <collision>
      <origin
        xyz="0 0 0"
        rpy="0 0 0" />
      <geometry>
        <mesh
          filename="package://cobod_arm_study/meshes/cobod_arm/Link_6.STL" />
      </geometry>
    </collision>
  </link>
  <joint
    name="Joint_5"
    type="revolute">
    <origin
      xyz="-0.585 0 0.122"
      rpy="0 0 0" />
    <parent
      link="Link_5" />
    <child
      link="Link_6" />
    <axis
      xyz="0 1 0" />
    <limit
      lower="-1.5707963268"
      upper="0.0"
      effort="6"
      velocity="1.0" />
  </joint>
  <link
    name="Gripper_base">
    <inertial>
      <origin
        xyz="-4.5193E-06 0.0005579 0.044226"
        rpy="0 0 0" />
      <mass
        value="0.28869" />
      <inertia
        ixx="0.00012313"
        ixy="-8.8747E-06"
        ixz="1.1977E-07"
        iyy="0.00013954"
        iyz="-2.1242E-06"
        izz="0.0002004" />
    </inertial>
    <visual>
      <origin
        xyz="0 0 0"
        rpy="0 0 0" />
      <geometry>
        <mesh
          filename="package://cobod_arm_study/meshes/cobod_arm/Gripper_base.STL" />
      </geometry>
      <material
        name="">
        <color
          rgba="0.75294 0.75294 0.75294 1" />
      </material>
    </visual>
    <collision>
      <origin
        xyz="0 0 0"
        rpy="0 0 0" />
      <geometry>
        <mesh
          filename="package://cobod_arm_study/meshes/cobod_arm/Gripper_base.STL" />
      </geometry>
    </collision>
  </link>
  <joint
    name="Joint_6"
    type="revolute">
    <origin
      xyz="0 -0.001 0.4354"
      rpy="0 0 0" />
    <parent
      link="Link_6" />
    <child
      link="Gripper_base" />
    <axis
      xyz="0 0 1" />
    <limit
      lower="-1.5707963268"
      upper="1.5707963268"
      effort="4"
      velocity="1.0" />
  </joint>

  <gazebo reference="Link_1">
    <material>Gazebo/Black</material>
  </gazebo>

<!--######################################################################-->
  <gazebo>
    <plugin name="gazebo_ros_control" filename="libgazebo_ros_control.so">
      <robotNamespace>/</robotNamespace>
      <controlPeriod>0.001</controlPeriod>
      <legacyModeNS>false</legacyModeNS>
    </plugin>
  </gazebo>

<!--######################################################################-->
  <gazebo>
    <plugin name="joint_state_publisher" filename="libgazebo_ros_joint_state_publisher.so">
      <jointName>Joint_1, Joint_2, Joint_3, Joint_5, Joint_6</jointName>
    </plugin>
  </gazebo>

</robot>
